<?xml version="1.0"?>
<robot name="differential_drive_robot" 
       xmlns:xacro="http://www.ros.org/wiki/xacro">

  <xacro:property name="wheel_radius" value="0.05"/>
  <xacro:property name="wheel_width" value="0.04"/>
  <xacro:property name="wheel_mass" value="0.1"/>

  <xacro:property name="bot_mass" value="0.2"/>
  <xacro:property name="bot_chassis_mass" value="0.6"/>

  <xacro:property name="bot_height" value="0.25"/>
  <xacro:property name="bot_length" value="0.17"/>
  <xacro:property name="bot_width" value="0.1"/>

  <!--Inertia Macros-->

  <!--Wheel Inertia-->
  <xacro:macro name="cylinder_inertia" params="m r h">
    <inertial>
      <origin xyz="0 0 0" rpy="0 0 0"/>
      <mass value="${m}"/>
      <inertia
        ixx="${(1/12)*m*(3*r*r+h*h)}"
        ixy="0" ixz="0"
        iyy="${(1/12)*m*(3*r*r+h*h)}"
        iyz="0"
        izz="${(1/2)*m*r*r}"/>
    </inertial>
  </xacro:macro>

  <xacro:macro name="wheel" params="name x_offset y_offset">
    <link name="${name}_wheel">
      <visual>
        <origin xyz="0 0 0" rpy="0 0 0"/>
        <geometry>
          <cylinder radius="${wheel_radius}" length="${wheel_width}"/>
        </geometry>
        <material name="black">
          <color rgba="0.1 0.1 0.1 1"/>
        </material>
      </visual>
      <collision>
        <origin xyz="0 0 0" rpy="0 0 0"/>
        <geometry>
          <cylinder radius="${wheel_radius}" length="${wheel_width}"/>
        </geometry>
      </collision>
      <xacro:cylinder_inertia m="${wheel_mass}" 
                              r="${wheel_radius}" 
                              h="${wheel_width}"/>
    </link>

    <joint name="${name}_wheel_joint" type="continuous">
      <parent link="base_link"/>
      <child link="${name}_wheel"/>
      <origin xyz="${x_offset} ${y_offset} -0.05" rpy="-1.5707 0 0"/>
      <axis xyz="0 0 1"/>
    </joint>
  </xacro:macro>

  <!--Base_Link_Inertia-->
  <xacro:macro name="box_inertia" params="m x y z cz">
    <inertial>
      <origin xyz="0 0 ${cz}" rpy="0 0 0"/>
      <mass value="${m}"/>
      <inertia
        ixx="${(1/12)*m*(y*y+z*z)}"
        ixy="0" ixz="0"
        iyy="${(1/12)*m*(x*x+z*z)}"
        iyz="0"
        izz="${(1/12)*m*(x*x+y*y)}"/>
    </inertial>
  </xacro:macro>

  <!--Base_Link-->

  <link name="base_link">
    <visual>
      <origin xyz="0 0 0.05" rpy="0 0 0"/>
      <geometry>
        <box size="${bot_length} ${bot_width} ${bot_height}"/>
      </geometry>
      <material name="blue">
        <color rgba="0 0 0.8 1"/>
      </material>
    </visual>
    <collision>
      <origin xyz="0 0 0.05" rpy="0 0 0"/>
      <geometry>
        <box size="${bot_length} ${bot_width} ${bot_height}"/>
      </geometry>
    </collision>
    <xacro:box_inertia m="${bot_chassis_mass}"
                       x="${bot_length}"
                       y="${bot_width}"
                       z="${bot_height}"
                       cz="0.225"/>
  </link>

  <xacro:wheel name="left" x_offset="0" y_offset="${0.08}"/>
  <xacro:wheel name="right" x_offset="0" y_offset="${-0.08}"/>

  <!--Dummy Base Footprint-->
  <link name="base_footprint"/>

  <joint name="base_footprint_joint" type="fixed">
      <parent link="base_footprint"/>
      <child link="base_link"/>
      <origin xyz="0 0 0" rpy="0 0 0"/>
  </joint>



  <!--Gazebo_Plugins-->

  <gazebo>
    <plugin filename="gz-sim-diff-drive-system"
            name="gz::sim::systems::DiffDrive">
      <left_joint>left_wheel_joint</left_joint>
      <right_joint>right_wheel_joint</right_joint>
      <wheel_separation>${2 * 0.08}</wheel_separation>
      <wheel_radius>${wheel_radius}</wheel_radius>
      <odom_publish_frequency>50</odom_publish_frequency>
      <topic>/cmd_vel</topic>
      <odom_topic>/odom</odom_topic>
      <frame_id>odom</frame_id>
      <child_frame_id>base_link</child_frame_id>
    </plugin>
  </gazebo>

  <gazebo reference="base_link">
    <sensor name="imu_sensor" type="imu">
      <always_on>1</always_on>
      <update_rate>100</update_rate>
      <topic>/imu</topic>
      <visualize>true</visualize>
      <plugin filename="gz-sim-imu-system"
              name="gz::sim::systems::Imu">
      </plugin>
    </sensor>
  </gazebo>


  

</robot>

